Workbook

Sheet Product info
A1: ID (ASIN/ EAN) | B1: Market | C1: Product name | D1: ASIN | E1: EAN | F1: SKU US | G1: SKU EU/UK | H1: SKU CA | I1: BSKU | J1: FNSKU US | K1: FNSKU EU/UK | L1: FNSKU CA | M1: Products/ carton | N1: Weight of outercarton (kg) | O1: Outercarton W (cm) | P1: Outercarton L (cm) | Q1: Outercarton H (cm) | R1: Innercarton weight (kg) | S1: Innercarton W (cm) | T1: Innercarton L (cm) | U1: Innercarton H (cm) | V1: Product W (cm) | W1: Product L (cm) | X1: Product H (cm) | Y1: Thickness (cm) | Z1: US HS-code | AA1: EU HS-code | AB1: UK HS-code | AC1: CA HS-code | AD1: China HS-code | AE1: Supplier | AF1: Leadtime (days) | AG1: MOQ (units) | AH1: Price (USD) | AI1: Brand | AJ1: Included in set | AK1: Material specifications | AL1: Colour | AM1: Label instruction for individual product | AN1: Packaging | AO1: Insert 1 | AP1: Insert 2 | AQ1: Insert 3 | AR1: Certificates US | AS1: Certificates UK | AT1: Certificates EU | AU1: Certificates CA | AV1: Compliance US | AW1: Compliance UK | AX1: Compliance EU | AY1: Compliance CA | AZ1: Additional comments and information US | BA1: Additional comments and information UK | BB1: Additional comments and information EU | BC1: Additional comments and information CA
A2: =IF(B2="AMZ",D2,E2) -> B0BNQV7QPR | B2: AMZ | C2: Blanket blossom UK | D2: B0BNQV7QPR | E2: 8720618229991 | F2: HC-7V8M-DTIF | G2: ZY-KHMF-162Z | J2: X003SFCT81 | K2: X001OHXU9T | M2: 52 | N2: 16.2 | O2: 46 | P2: 56 | Q2: 55 | R2: 0.29 | S2: 22 | T2: 27 | U2: 3.8 | V2: 115 | W2: 115 | Y2: 0.02 | Z2: 6301300020 | AA2: 6301301000 | AB2: 6301301000 | AD2: 6301300000 | AE2: Kevin | AG2: 100 | AH2: 4.5 | AI2: Odoxia | AJ2: 1pc milestone blanket, 1 wooden arrow. 1 wooden circle. 1 double sided wooden frame with text | AK2: 100% Cotton | AM2: washing label | AN2: custom carton box with transparent opening
A3: =IF(B3="AMZ",D3,E3) -> B08CKW16F7 | B3: AMZ | C3: Blanket fox | D3: B08CKW16F7 | E3: 8719992661510 | G3: MX-8YB2-6ZXD | K3: X0017BQCGZ | M3: 50 | N3: 20 | O3: 45 | P3: 50 | Q3: 55 | R3: 0.32 | S3: 25 | T3: 26 | U3: 8 | Z3: 6301400010 | AA3: 6301401000 | AB3: 6301909099 | AD3: 63014000 | AE3: Fiona | AG3: 100 | AH3: 2.95 | AI3: Odoxia | AJ3: Blanket, four frames, packaged in ribbon with card with design on it | AK3: 100*130cm | AM3: washing label | AN3: adhesive bag
A4: =IF(B4="AMZ",D4,E4) -> B07NS8B464 | B4: AMZ | C4: Blanket koala | D4: B07NS8B464 | E4: 8719992661992 | G4: 5Y-3YWH-201Z | M4: 60 | N4: 19 | O4: 45 | P4: 50 | Q4: 55 | R4: 0.28 | S4: 25 | T4: 26 | U4: 6 | Z4: 6301400010 | AA4: 6301401000 | AB4: 6301909099 | AD4: 63014000 | AE4: Fiona | AG4: 100 | AH4: 2.95 | AI4: Odoxia | AJ4: Blanket, four frames, packaged in ribbon with card with design on it | AK4: 100% Polyester | AM4: washing label | AN4: adhesive pe bag
A5: =IF(B5="AMZ",D5,E5) -> B09NDXFBWY | B5: AMZ | C5: Blanket Leaves DE | D5: B09NDXFBWY | E5: 8720618229304 | G5: 8L-9IFE-6T24 | K5: X001HH9ZU9 | M5: 52 | N5: 19 | O5: 46 | P5: 56 | Q5: 55 | R5: 0.29 | S5: 22 | T5: 27 | U5: 3.8 | V5: 115 | W5: 115 | Y5: 0.02 | Z5: 6301300020 | AA5: 6301301000 | AD5: 6301300000 | AE5: Kevin | AG5: 100 | AH5: 4.5 | AI5: Odoxia | AJ5: 1pc milestone blanket, 1 wooden arrow. 1 wooden circle. 1 double sided wooden frame with text | AK5: 100% Cotton | AL5: White | AM5: washing label | AN5: custom carton box with transparent opening | AO5: A6 double-sided colored thank you note
A6: =IF(B6="AMZ",D6,E6) -> B08BG74Q65 | B6: AMZ | C6: Propagator big 1pk | D6: B08BG74Q65 | E6: 8719992661619 | G6: 7E-GZIK-FILJ | J6: X002MXF1K3 | K6: X0016ZYZVB | M6: 6 | N6: 5.5 | O6: 51.5 | P6: 39.7 | Q6: 46.5 | R6: 0.84 | S6: 28 | T6: 24 | U6: 18 | Z6: 3926901000 | AA6: 3926909790 | AB6: 3926909790 | AD6: 3926909090 | AE6: Joyce | AG6: 1000 | AH6: 4.05 | AI6: Leafimpact | AJ6: 24-cell seed tray propagator, with 4pc marker , 2pc seed planter, thanks card and guide | AK6: Plastic | AM6: Provided by us | AN6: Color box | AO6: A6 double-sided colored thank you note | AP6: A5 double-sided colored manual
A7: =IF(B7="AMZ",D7,E7) -> 8719992661190 | B7: BOL | C7: propagator big 2pk | E7: 8719992661190 | I7: 2950025924547 | M7: 6 | N7: 9.9 | O7: 40 | P7: 52 | Q7: 59 | R7: 1.5 | S7: 25 | T7: 39 | U7: 19 | V7: 38 | W7: 24 | X7: 18 | Y7: 13 | AA7: 3926909790 | AD7: 3926909000 | AE7: Louise | AF7: 30 | AG7: 100 | AH7: 5.27 | AI7: LeafImpact | AJ7: 2 Lids + 2 bottoms + 2x 24 cell seed trays + 2pc seed planter +8 labels | AK7: Plastic | AL7: Green | AN7: custom brown box with black text and green color | AO7: A6 double-sided colored thank you note | AP7: A5 double-sided colored manual
A8: =IF(B8="AMZ",D8,E8) -> B08BG695P2 | B8: AMZ | C8: Propagator big 2pk | D8: B08BG695P2 | E8: 8719992661190 | G8: FP-S3KC-OPLV | J8: X002MXGIJB | K8: X0016ZRH7F | M8: 6 | N8: 9.2 | O8: 51.5 | P8: 39.7 | Q8: 55.5 | R8: 1.43 | S8: 38 | T8: 24 | U8: 18 | V8: 24 | W8: 38 | X8: 16 | Z8: 3926901000 | AA8: 3926909790 | AB8: 3926909790 | AD8: 3926909090 | AE8: Samantha | AG8: 1000 | AH8: 6.07 | AI8: Leafimpact | AJ8: 24-cell seed tray propagator, with 8pc marker , 2pc seed planter, thanks card and guide | AK8: Plastic | AM8: Provided by us | AN8: Color box | AO8: A6 double-sided colored thank you note | AP8: A5 double-sided colored manual
A9: =IF(B9="AMZ",D9,E9) -> B07Q3FVXS9 | B9: AMZ | C9: Rabbit blanket | D9: B07Q3FVXS9 | E9: 8719992661985 | G9: EW-IO2U-1J4Q | M9: 60 | N9: 19 | O9: 45 | P9: 50 | Q9: 55 | R9: 0.28 | S9: 25 | T9: 26 | U9: 6 | AD9: 63014000 | AE9: Fiona | AG9: 100 | AH9: 2.95 | AI9: Odoxia | AJ9: Blanket, four frames, packaged in ribbon with card with design on it | AK9: 100% Polyester | AM9: washing label | AN9: adhesive pe bag
A10: =IF(B10="AMZ",D10,E10) -> 8720618229946 | B10: BOL | C10: Record holder black | E10: 8720618229946 | I10: 2950027619786 | M10: 13 | N10: 11.3 | O10: 26 | P10: 44 | Q10: 39.5 | R10: 0.8 | S10: 24 | T10: 36.5 | U10: 2.7 | V10: 35 | W10: 18 | X10: 18 | AA10: 4421999999 | AD10: 4421999090 | AE10: Chris Wang | AG10: 100 | AH10: 5.15 | AI10: Odoxia | AJ10: vinyl record stand*2，acrylic board*2,connecting rod*2, screwdriver *1, screws*4, Non-slip pad*8 | AK10: Wood & Acrylic | AN10: box | AO10: A6 double-sided colored thank you note | AP10: A5 double-sided colored manual
A11: =IF(B11="AMZ",D11,E11) -> 8720618229953 | B11: BOL | C11: Record holder light | E11: 8720618229953 | I11: 2950027619809 | M11: 13 | N11: 11.3 | O11: 26 | P11: 44 | Q11: 39.5 | R11: 0.8 | S11: 24 | T11: 36.5 | U11: 2.7 | V11: 35 | W11: 18 | X11: 18 | AA11: 3926909790 | AD11: 4421999090 | AE11: Chris Wang | AG11: 100 | AH11: 5.15 | AI11: Odoxia | AJ11: vinyl record stand*2，acrylic board*2,connecting rod*2, screwdriver *1, screws*4, Non-slip pad*8 | AK11: Wood & Acrylic | AN11: box | AO11: A6 double-sided colored thank you note | AP11: A5 double-sided colored manual
A12: =IF(B12="AMZ",D12,E12) -> 0
A13: =IF(B13="AMZ",D13,E13) -> 0
A14: =IF(B14="AMZ",D14,E14) -> 0
A15: =IF(B15="AMZ",D15,E15) -> 0
A16: =IF(B16="AMZ",D16,E16) -> 0
A17: =IF(B17="AMZ",D17,E17) -> 0
A18: =IF(B18="AMZ",D18,E18) -> 0
A19: =IF(B19="AMZ",D19,E19) -> 0
A20: =IF(B20="AMZ",D20,E20) -> 0
A21: =IF(B21="AMZ",D21,E21) -> 0
A22: =IF(B22="AMZ",D22,E22) -> 0
A23: =IF(B23="AMZ",D23,E23) -> 0
... A185: =IF(B185="AMZ",D185,E185) -> 0

Sheet Dimensions
E1: Outercarton | P1: Innercarton
A2: ASIN/EAN | B2: SKU US | C2: SKU EU/UK | D2: SKU CA | E2: Dimensions (cm) | F2: W (cm) | G2: L (cm) | H2: H (CM) | I2: Weight (kg) | J2: Units per carton | K2: CBM | L2: W (inch) | M2: L (inch) | N2: H (inch) | O2: Weight (lbs) | P2: Dimensions (cm) | Q2: W (cm) | R2: L (cm) | S2: H (CM) | T2: Weight (kg) | U2: CBM | V2: W (inch) | W2: L (inch) | X2: H (inch) | Y2: Weight (lbs) | Z2: Shipping volume per unit (CBM)
A3: ='Product info'!#REF! -> #REF! | B3: ='Product info'!#REF! -> #REF! | C3: ='Product info'!#REF! -> #REF! | D3: ='Product info'!#REF! -> #REF! | E3: =F3&"*"&G3&"*"&H3 -> #REF! | F3: ='Product info'!#REF! -> #REF! | G3: ='Product info'!#REF! -> #REF! | H3: ='Product info'!#REF! -> #REF! | I3: ='Product info'!#REF! -> #REF! | J3: ='Product info'!#REF! -> #REF! | K3: =F3*G3*H3/(100*100*100) -> #REF! | L3: =F3*0.393701 -> #REF! | M3: =G3*0.393701 -> #REF! | N3: =H3*0.393701 -> #REF! | O3: =I3*2.20462 -> #REF! | P3: =Q3&"*"&R3&"*"&S3 -> #REF! | Q3: ='Product info'!#REF! -> #REF! | R3: ='Product info'!#REF! -> #REF! | S3: ='Product info'!#REF! -> #REF! | T3: ='Product info'!#REF! -> #REF! | U3: =Q3*R3*S3/(100*100*100) -> #REF! | V3: =Q3*0.393701 -> #REF! | W3: =R3*0.393701 -> #REF! | X3: =S3*0.393701 -> #REF! | Y3: =T3*2.20462 -> #REF! | Z3: =K3/J3 -> #REF!
A4: ='Product info'!#REF! -> #REF! | B4: ='Product info'!#REF! -> #REF! | C4: ='Product info'!#REF! -> #REF! | D4: ='Product info'!#REF! -> #REF! | E4: =F4&"*"&G4&"*"&H4 -> #REF! | F4: ='Product info'!#REF! -> #REF! | G4: ='Product info'!#REF! -> #REF! | H4: ='Product info'!#REF! -> #REF! | I4: ='Product info'!#REF! -> #REF! | J4: ='Product info'!#REF! -> #REF! | K4: =F4*G4*H4/(100*100*100) -> #REF! | L4: =F4*0.393701 -> #REF! | M4: =G4*0.393701 -> #REF! | N4: =H4*0.393701 -> #REF! | O4: =I4*2.20462 -> #REF! | P4: =Q4&"*"&R4&"*"&S4 -> #REF! | Q4: ='Product info'!#REF! -> #REF! | R4: ='Product info'!#REF! -> #REF! | S4: ='Product info'!#REF! -> #REF! | T4: ='Product info'!#REF! -> #REF! | U4: =Q4*R4*S4/(100*100*100) -> #REF! | V4: =Q4*0.393701 -> #REF! | W4: =R4*0.393701 -> #REF! | X4: =S4*0.393701 -> #REF! | Y4: =T4*2.20462 -> #REF! | Z4: =K4/J4 -> #REF!
A5: ='Product info'!#REF! -> #REF! | B5: ='Product info'!#REF! -> #REF! | C5: ='Product info'!#REF! -> #REF! | D5: ='Product info'!#REF! -> #REF! | E5: =F5&"*"&G5&"*"&H5 -> #REF! | F5: ='Product info'!#REF! -> #REF! | G5: ='Product info'!#REF! -> #REF! | H5: ='Product info'!#REF! -> #REF! | I5: ='Product info'!#REF! -> #REF! | J5: ='Product info'!#REF! -> #REF! | K5: =F5*G5*H5/(100*100*100) -> #REF! | L5: =F5*0.393701 -> #REF! | M5: =G5*0.393701 -> #REF! | N5: =H5*0.393701 -> #REF! | O5: =I5*2.20462 -> #REF! | P5: =Q5&"*"&R5&"*"&S5 -> #REF! | Q5: ='Product info'!#REF! -> #REF! | R5: ='Product info'!#REF! -> #REF! | S5: ='Product info'!#REF! -> #REF! | T5: ='Product info'!#REF! -> #REF! | U5: =Q5*R5*S5/(100*100*100) -> #REF! | V5: =Q5*0.393701 -> #REF! | W5: =R5*0.393701 -> #REF! | X5: =S5*0.393701 -> #REF! | Y5: =T5*2.20462 -> #REF! | Z5: =K5/J5 -> #REF!
A6: ='Product info'!#REF! -> #REF! | B6: ='Product info'!#REF! -> #REF! | C6: ='Product info'!#REF! -> #REF! | D6: ='Product info'!#REF! -> #REF! | E6: =F6&"*"&G6&"*"&H6 -> #REF! | F6: ='Product info'!#REF! -> #REF! | G6: ='Product info'!#REF! -> #REF! | H6: ='Product info'!#REF! -> #REF! | I6: ='Product info'!#REF! -> #REF! | J6: ='Product info'!#REF! -> #REF! | K6: =F6*G6*H6/(100*100*100) -> #REF! | L6: =F6*0.393701 -> #REF! | M6: =G6*0.393701 -> #REF! | N6: =H6*0.393701 -> #REF! | O6: =I6*2.20462 -> #REF! | P6: =Q6&"*"&R6&"*"&S6 -> #REF! | Q6: ='Product info'!#REF! -> #REF! | R6: ='Product info'!#REF! -> #REF! | S6: ='Product info'!#REF! -> #REF! | T6: ='Product info'!#REF! -> #REF! | U6: =Q6*R6*S6/(100*100*100) -> #REF! | V6: =Q6*0.393701 -> #REF! | W6: =R6*0.393701 -> #REF! | X6: =S6*0.393701 -> #REF! | Y6: =T6*2.20462 -> #REF! | Z6: =K6/J6 -> #REF!
A7: ='Product info'!#REF! -> #REF! | B7: ='Product info'!#REF! -> #REF! | C7: ='Product info'!#REF! -> #REF! | D7: ='Product info'!#REF! -> #REF! | E7: =F7&"*"&G7&"*"&H7 -> #REF! | F7: ='Product info'!#REF! -> #REF! | G7: ='Product info'!#REF! -> #REF! | H7: ='Product info'!#REF! -> #REF! | I7: ='Product info'!#REF! -> #REF! | J7: ='Product info'!#REF! -> #REF! | K7: =F7*G7*H7/(100*100*100) -> #REF! | L7: =F7*0.393701 -> #REF! | M7: =G7*0.393701 -> #REF! | N7: =H7*0.393701 -> #REF! | O7: =I7*2.20462 -> #REF! | P7: =Q7&"*"&R7&"*"&S7 -> #REF! | Q7: ='Product info'!#REF! -> #REF! | R7: ='Product info'!#REF! -> #REF! | S7: ='Product info'!#REF! -> #REF! | T7: ='Product info'!#REF! -> #REF! | U7: =Q7*R7*S7/(100*100*100) -> #REF! | V7: =Q7*0.393701 -> #REF! | W7: =R7*0.393701 -> #REF! | X7: =S7*0.393701 -> #REF! | Y7: =T7*2.20462 -> #REF! | Z7: =K7/J7 -> #REF!
A8: ='Product info'!#REF! -> #REF! | B8: ='Product info'!#REF! -> #REF! | C8: ='Product info'!#REF! -> #REF! | D8: ='Product info'!#REF! -> #REF! | E8: =F8&"*"&G8&"*"&H8 -> #REF! | F8: ='Product info'!#REF! -> #REF! | G8: ='Product info'!#REF! -> #REF! | H8: ='Product info'!#REF! -> #REF! | I8: ='Product info'!#REF! -> #REF! | J8: ='Product info'!#REF! -> #REF! | K8: =F8*G8*H8/(100*100*100) -> #REF! | L8: =F8*0.393701 -> #REF! | M8: =G8*0.393701 -> #REF! | N8: =H8*0.393701 -> #REF! | O8: =I8*2.20462 -> #REF! | P8: =Q8&"*"&R8&"*"&S8 -> #REF! | Q8: ='Product info'!#REF! -> #REF! | R8: ='Product info'!#REF! -> #REF! | S8: ='Product info'!#REF! -> #REF! | T8: ='Product info'!#REF! -> #REF! | U8: =Q8*R8*S8/(100*100*100) -> #REF! | V8: =Q8*0.393701 -> #REF! | W8: =R8*0.393701 -> #REF! | X8: =S8*0.393701 -> #REF! | Y8: =T8*2.20462 -> #REF! | Z8: =K8/J8 -> #REF!
A9: ='Product info'!#REF! -> #REF! | B9: ='Product info'!#REF! -> #REF! | C9: ='Product info'!#REF! -> #REF! | D9: ='Product info'!#REF! -> #REF! | E9: =F9&"*"&G9&"*"&H9 -> #REF! | F9: ='Product info'!#REF! -> #REF! | G9: ='Product info'!#REF! -> #REF! | H9: ='Product info'!#REF! -> #REF! | I9: ='Product info'!#REF! -> #REF! | J9: ='Product info'!#REF! -> #REF! | K9: =F9*G9*H9/(100*100*100) -> #REF! | L9: =F9*0.393701 -> #REF! | M9: =G9*0.393701 -> #REF! | N9: =H9*0.393701 -> #REF! | O9: =I9*2.20462 -> #REF! | P9: =Q9&"*"&R9&"*"&S9 -> #REF! | Q9: ='Product info'!#REF! -> #REF! | R9: ='Product info'!#REF! -> #REF! | S9: ='Product info'!#REF! -> #REF! | T9: ='Product info'!#REF! -> #REF! | U9: =Q9*R9*S9/(100*100*100) -> #REF! | V9: =Q9*0.393701 -> #REF! | W9: =R9*0.393701 -> #REF! | X9: =S9*0.393701 -> #REF! | Y9: =T9*2.20462 -> #REF! | Z9: =K9/J9 -> #REF!
A10: ='Product info'!#REF! -> #REF! | B10: ='Product info'!#REF! -> #REF! | C10: ='Product info'!#REF! -> #REF! | D10: ='Product info'!#REF! -> #REF! | E10: =F10&"*"&G10&"*"&H10 -> #REF! | F10: ='Product info'!#REF! -> #REF! | G10: ='Product info'!#REF! -> #REF! | H10: ='Product info'!#REF! -> #REF! | I10: ='Product info'!#REF! -> #REF! | J10: ='Product info'!#REF! -> #REF! | K10: =F10*G10*H10/(100*100*100) -> #REF! | L10: =F10*0.393701 -> #REF! | M10: =G10*0.393701 -> #REF! | N10: =H10*0.393701 -> #REF! | O10: =I10*2.20462 -> #REF! | P10: =Q10&"*"&R10&"*"&S10 -> #REF! | Q10: ='Product info'!#REF! -> #REF! | R10: ='Product info'!#REF! -> #REF! | S10: ='Product info'!#REF! -> #REF! | T10: ='Product info'!#REF! -> #REF! | U10: =Q10*R10*S10/(100*100*100) -> #REF! | V10: =Q10*0.393701 -> #REF! | W10: =R10*0.393701 -> #REF! | X10: =S10*0.393701 -> #REF! | Y10: =T10*2.20462 -> #REF! | Z10: =K10/J10 -> #REF!
A11: ='Product info'!#REF! -> #REF! | B11: ='Product info'!#REF! -> #REF! | C11: ='Product info'!#REF! -> #REF! | D11: ='Product info'!#REF! -> #REF! | E11: =F11&"*"&G11&"*"&H11 -> #REF! | F11: ='Product info'!#REF! -> #REF! | G11: ='Product info'!#REF! -> #REF! | H11: ='Product info'!#REF! -> #REF! | I11: ='Product info'!#REF! -> #REF! | J11: ='Product info'!#REF! -> #REF! | K11: =F11*G11*H11/(100*100*100) -> #REF! | L11: =F11*0.393701 -> #REF! | M11: =G11*0.393701 -> #REF! | N11: =H11*0.393701 -> #REF! | O11: =I11*2.20462 -> #REF! | P11: =Q11&"*"&R11&"*"&S11 -> #REF! | Q11: ='Product info'!#REF! -> #REF! | R11: ='Product info'!#REF! -> #REF! | S11: ='Product info'!#REF! -> #REF! | T11: ='Product info'!#REF! -> #REF! | U11: =Q11*R11*S11/(100*100*100) -> #REF! | V11: =Q11*0.393701 -> #REF! | W11: =R11*0.393701 -> #REF! | X11: =S11*0.393701 -> #REF! | Y11: =T11*2.20462 -> #REF! | Z11: =K11/J11 -> #REF!
A12: ='Product info'!#REF! -> #REF! | B12: ='Product info'!#REF! -> #REF! | C12: ='Product info'!#REF! -> #REF! | D12: ='Product info'!#REF! -> #REF! | E12: =F12&"*"&G12&"*"&H12 -> #REF! | F12: ='Product info'!#REF! -> #REF! | G12: ='Product info'!#REF! -> #REF! | H12: ='Product info'!#REF! -> #REF! | I12: ='Product info'!#REF! -> #REF! | J12: ='Product info'!#REF! -> #REF! | K12: =F12*G12*H12/(100*100*100) -> #REF! | L12: =F12*0.393701 -> #REF! | M12: =G12*0.393701 -> #REF! | N12: =H12*0.393701 -> #REF! | O12: =I12*2.20462 -> #REF! | P12: =Q12&"*"&R12&"*"&S12 -> #REF! | Q12: ='Product info'!#REF! -> #REF! | R12: ='Product info'!#REF! -> #REF! | S12: ='Product info'!#REF! -> #REF! | T12: ='Product info'!#REF! -> #REF! | U12: =Q12*R12*S12/(100*100*100) -> #REF! | V12: =Q12*0.393701 -> #REF! | W12: =R12*0.393701 -> #REF! | X12: =S12*0.393701 -> #REF! | Y12: =T12*2.20462 -> #REF! | Z12: =K12/J12 -> #REF!
A13: ='Product info'!#REF! -> #REF! | B13: ='Product info'!#REF! -> #REF! | C13: ='Product info'!#REF! -> #REF! | D13: ='Product info'!#REF! -> #REF! | E13: =F13&"*"&G13&"*"&H13 -> #REF! | F13: ='Product info'!#REF! -> #REF! | G13: ='Product info'!#REF! -> #REF! | H13: ='Product info'!#REF! -> #REF! | I13: ='Product info'!#REF! -> #REF! | J13: ='Product info'!#REF! -> #REF! | K13: =F13*G13*H13/(100*100*100) -> #REF! | L13: =F13*0.393701 -> #REF! | M13: =G13*0.393701 -> #REF! | N13: =H13*0.393701 -> #REF! | O13: =I13*2.20462 -> #REF! | P13: =Q13&"*"&R13&"*"&S13 -> #REF! | Q13: ='Product info'!#REF! -> #REF! | R13: ='Product info'!#REF! -> #REF! | S13: ='Product info'!#REF! -> #REF! | T13: ='Product info'!#REF! -> #REF! | U13: =Q13*R13*S13/(100*100*100) -> #REF! | V13: =Q13*0.393701 -> #REF! | W13: =R13*0.393701 -> #REF! | X13: =S13*0.393701 -> #REF! | Y13: =T13*2.20462 -> #REF! | Z13: =K13/J13 -> #REF!
A14: ='Product info'!#REF! -> #REF! | B14: ='Product info'!#REF! -> #REF! | C14: ='Product info'!#REF! -> #REF! | D14: ='Product info'!#REF! -> #REF! | E14: =F14&"*"&G14&"*"&H14 -> #REF! | F14: ='Product info'!#REF! -> #REF! | G14: ='Product info'!#REF! -> #REF! | H14: ='Product info'!#REF! -> #REF! | I14: ='Product info'!#REF! -> #REF! | J14: ='Product info'!#REF! -> #REF! | K14: =F14*G14*H14/(100*100*100) -> #REF! | L14: =F14*0.393701 -> #REF! | M14: =G14*0.393701 -> #REF! | N14: =H14*0.393701 -> #REF! | O14: =I14*2.20462 -> #REF! | P14: =Q14&"*"&R14&"*"&S14 -> #REF! | Q14: ='Product info'!#REF! -> #REF! | R14: ='Product info'!#REF! -> #REF! | S14: ='Product info'!#REF! -> #REF! | T14: ='Product info'!#REF! -> #REF! | U14: =Q14*R14*S14/(100*100*100) -> #REF! | V14: =Q14*0.393701 -> #REF! | W14: =R14*0.393701 -> #REF! | X14: =S14*0.393701 -> #REF! | Y14: =T14*2.20462 -> #REF! | Z14: =K14/J14 -> #REF!
... A39: ='Product info'!#REF! -> #REF! | B39: ='Product info'!#REF! -> #REF! | C39: ='Product info'!#REF! -> #REF! | D39: ='Product info'!#REF! -> #REF! | E39: =F39&"*"&G39&"*"&H39 -> #REF! | F39: ='Product info'!#REF! -> #REF! | G39: ='Product info'!#REF! -> #REF! | H39: ='Product info'!#REF! -> #REF! | I39: ='Product info'!#REF! -> #REF! | J39: ='Product info'!#REF! -> #REF! | K39: =F39*G39*H39/(100*100*100) -> #REF! | L39: =F39*0.393701 -> #REF! | M39: =G39*0.393701 -> #REF! | N39: =H39*0.393701 -> #REF! | O39: =I39*2.20462 -> #REF! | P39: =Q39&"*"&R39&"*"&S39 -> #REF! | Q39: ='Product info'!#REF! -> #REF! | R39: ='Product info'!#REF! -> #REF! | S39: ='Product info'!#REF! -> #REF! | T39: ='Product info'!#REF! -> #REF! | U39: =Q39*R39*S39/(100*100*100) -> #REF! | V39: =Q39*0.393701 -> #REF! | W39: =R39*0.393701 -> #REF! | X39: =S39*0.393701 -> #REF! | Y39: =T39*2.20462 -> #REF! | Z39: =K39/J39 -> #REF!
A40: ='Product info'!A2 -> B0BNQV7QPR | B40: ='Product info'!F2 -> HC-7V8M-DTIF | C40: ='Product info'!G2 -> ZY-KHMF-162Z | D40: ='Product info'!H2 -> 0 | E40: =F40&"*"&G40&"*"&H40 -> 46*56*55 | F40: ='Product info'!O2 -> 46 | G40: ='Product info'!P2 -> 56 | H40: ='Product info'!Q2 -> 55 | I40: ='Product info'!N2 -> 16.2 | J40: ='Product info'!M2 -> 52 | K40: =F40*G40*H40/(100*100*100) -> 0.14168 | L40: =F40*0.393701 -> 18.110246 | M40: =G40*0.393701 -> 22.047256 | N40: =H40*0.393701 -> 21.653555 | O40: =I40*2.20462 -> 35.714844 | P40: =Q40&"*"&R40&"*"&S40 -> 22*27*3.8 | Q40: ='Product info'!S2 -> 22 | R40: ='Product info'!T2 -> 27 | S40: ='Product info'!U2 -> 3.8 | T40: ='Product info'!R2 -> 0.29 | U40: =Q40*R40*S40/(100*100*100) -> 0.0022572 | V40: =Q40*0.393701 -> 8.661422 | W40: =R40*0.393701 -> 10.629927 | X40: =S40*0.393701 -> 1.4960638 | Y40: =T40*2.20462 -> 0.6393398 | Z40: =K40/J40 -> 0.0027246154
A41: ='Product info'!A3 -> B08CKW16F7 | B41: ='Product info'!F3 -> 0 | C41: ='Product info'!G3 -> MX-8YB2-6ZXD | D41: ='Product info'!H3 -> 0 | E41: =F41&"*"&G41&"*"&H41 -> 45*50*55 | F41: ='Product info'!O3 -> 45 | G41: ='Product info'!P3 -> 50 | H41: ='Product info'!Q3 -> 55 | I41: ='Product info'!N3 -> 20 | J41: ='Product info'!M3 -> 50 | K41: =F41*G41*H41/(100*100*100) -> 0.12375 | L41: =F41*0.393701 -> 17.716545 | M41: =G41*0.393701 -> 19.68505 | N41: =H41*0.393701 -> 21.653555 | O41: =I41*2.20462 -> 44.0924 | P41: =Q41&"*"&R41&"*"&S41 -> 25*26*8 | Q41: ='Product info'!S3 -> 25 | R41: ='Product info'!T3 -> 26 | S41: ='Product info'!U3 -> 8 | T41: ='Product info'!R3 -> 0.32 | U41: =Q41*R41*S41/(100*100*100) -> 0.0052 | V41: =Q41*0.393701 -> 9.842525 | W41: =R41*0.393701 -> 10.236226 | X41: =S41*0.393701 -> 3.149608 | Y41: =T41*2.20462 -> 0.7054784 | Z41: =K41/J41 -> 0.002475
A42: ='Product info'!A4 -> B07NS8B464 | B42: ='Product info'!F4 -> 0 | C42: ='Product info'!G4 -> 5Y-3YWH-201Z | D42: ='Product info'!H4 -> 0 | E42: =F42&"*"&G42&"*"&H42 -> 45*50*55 | F42: ='Product info'!O4 -> 45 | G42: ='Product info'!P4 -> 50 | H42: ='Product info'!Q4 -> 55 | I42: ='Product info'!N4 -> 19 | J42: ='Product info'!M4 -> 60 | K42: =F42*G42*H42/(100*100*100) -> 0.12375 | L42: =F42*0.393701 -> 17.716545 | M42: =G42*0.393701 -> 19.68505 | N42: =H42*0.393701 -> 21.653555 | O42: =I42*2.20462 -> 41.88778 | P42: =Q42&"*"&R42&"*"&S42 -> 25*26*6 | Q42: ='Product info'!S4 -> 25 | R42: ='Product info'!T4 -> 26 | S42: ='Product info'!U4 -> 6 | T42: ='Product info'!R4 -> 0.28 | U42: =Q42*R42*S42/(100*100*100) -> 0.0039 | V42: =Q42*0.393701 -> 9.842525 | W42: =R42*0.393701 -> 10.236226 | X42: =S42*0.393701 -> 2.362206 | Y42: =T42*2.20462 -> 0.6172936 | Z42: =K42/J42 -> 0.0020625
A43: ='Product info'!A5 -> B09NDXFBWY | B43: ='Product info'!F5 -> 0 | C43: ='Product info'!G5 -> 8L-9IFE-6T24 | D43: ='Product info'!H5 -> 0 | E43: =F43&"*"&G43&"*"&H43 -> 46*56*55 | F43: ='Product info'!O5 -> 46 | G43: ='Product info'!P5 -> 56 | H43: ='Product info'!Q5 -> 55 | I43: ='Product info'!N5 -> 19 | J43: ='Product info'!M5 -> 52 | K43: =F43*G43*H43/(100*100*100) -> 0.14168 | L43: =F43*0.393701 -> 18.110246 | M43: =G43*0.393701 -> 22.047256 | N43: =H43*0.393701 -> 21.653555 | O43: =I43*2.20462 -> 41.88778 | P43: =Q43&"*"&R43&"*"&S43 -> 22*27*3.8 | Q43: ='Product info'!S5 -> 22 | R43: ='Product info'!T5 -> 27 | S43: ='Product info'!U5 -> 3.8 | T43: ='Product info'!R5 -> 0.29 | U43: =Q43*R43*S43/(100*100*100) -> 0.0022572 | V43: =Q43*0.393701 -> 8.661422 | W43: =R43*0.393701 -> 10.629927 | X43: =S43*0.393701 -> 1.4960638 | Y43: =T43*2.20462 -> 0.6393398 | Z43: =K43/J43 -> 0.0027246154
A44: ='Product info'!#REF! -> #REF! | B44: ='Product info'!#REF! -> #REF! | C44: ='Product info'!#REF! -> #REF! | D44: ='Product info'!#REF! -> #REF! | E44: =F44&"*"&G44&"*"&H44 -> #REF! | F44: ='Product info'!#REF! -> #REF! | G44: ='Product info'!#REF! -> #REF! | H44: ='Product info'!#REF! -> #REF! | I44: ='Product info'!#REF! -> #REF! | J44: ='Product info'!#REF! -> #REF! | K44: =F44*G44*H44/(100*100*100) -> #REF! | L44: =F44*0.393701 -> #REF! | M44: =G44*0.393701 -> #REF! | N44: =H44*0.393701 -> #REF! | O44: =I44*2.20462 -> #REF! | P44: =Q44&"*"&R44&"*"&S44 -> #REF! | Q44: ='Product info'!#REF! -> #REF! | R44: ='Product info'!#REF! -> #REF! | S44: ='Product info'!#REF! -> #REF! | T44: ='Product info'!#REF! -> #REF! | U44: =Q44*R44*S44/(100*100*100) -> #REF! | V44: =Q44*0.393701 -> #REF! | W44: =R44*0.393701 -> #REF! | X44: =S44*0.393701 -> #REF! | Y44: =T44*2.20462 -> #REF! | Z44: =K44/J44 -> #REF!
A45: ='Product info'!#REF! -> #REF! | B45: ='Product info'!#REF! -> #REF! | C45: ='Product info'!#REF! -> #REF! | D45: ='Product info'!#REF! -> #REF! | E45: =F45&"*"&G45&"*"&H45 -> #REF! | F45: ='Product info'!#REF! -> #REF! | G45: ='Product info'!#REF! -> #REF! | H45: ='Product info'!#REF! -> #REF! | I45: ='Product info'!#REF! -> #REF! | J45: ='Product info'!#REF! -> #REF! | K45: =F45*G45*H45/(100*100*100) -> #REF! | L45: =F45*0.393701 -> #REF! | M45: =G45*0.393701 -> #REF! | N45: =H45*0.393701 -> #REF! | O45: =I45*2.20462 -> #REF! | P45: =Q45&"*"&R45&"*"&S45 -> #REF! | Q45: ='Product info'!#REF! -> #REF! | R45: ='Product info'!#REF! -> #REF! | S45: ='Product info'!#REF! -> #REF! | T45: ='Product info'!#REF! -> #REF! | U45: =Q45*R45*S45/(100*100*100) -> #REF! | V45: =Q45*0.393701 -> #REF! | W45: =R45*0.393701 -> #REF! | X45: =S45*0.393701 -> #REF! | Y45: =T45*2.20462 -> #REF! | Z45: =K45/J45 -> #REF!
A46: ='Product info'!#REF! -> #REF! | B46: ='Product info'!#REF! -> #REF! | C46: ='Product info'!#REF! -> #REF! | D46: ='Product info'!#REF! -> #REF! | E46: =F46&"*"&G46&"*"&H46 -> #REF! | F46: ='Product info'!#REF! -> #REF! | G46: ='Product info'!#REF! -> #REF! | H46: ='Product info'!#REF! -> #REF! | I46: ='Product info'!#REF! -> #REF! | J46: ='Product info'!#REF! -> #REF! | K46: =F46*G46*H46/(100*100*100) -> #REF! | L46: =F46*0.393701 -> #REF! | M46: =G46*0.393701 -> #REF! | N46: =H46*0.393701 -> #REF! | O46: =I46*2.20462 -> #REF! | P46: =Q46&"*"&R46&"*"&S46 -> #REF! | Q46: ='Product info'!#REF! -> #REF! | R46: ='Product info'!#REF! -> #REF! | S46: ='Product info'!#REF! -> #REF! | T46: ='Product info'!#REF! -> #REF! | U46: =Q46*R46*S46/(100*100*100) -> #REF! | V46: =Q46*0.393701 -> #REF! | W46: =R46*0.393701 -> #REF! | X46: =S46*0.393701 -> #REF! | Y46: =T46*2.20462 -> #REF! | Z46: =K46/J46 -> #REF!
A47: ='Product info'!#REF! -> #REF! | B47: ='Product info'!#REF! -> #REF! | C47: ='Product info'!#REF! -> #REF! | D47: ='Product info'!#REF! -> #REF! | E47: =F47&"*"&G47&"*"&H47 -> #REF! | F47: ='Product info'!#REF! -> #REF! | G47: ='Product info'!#REF! -> #REF! | H47: ='Product info'!#REF! -> #REF! | I47: ='Product info'!#REF! -> #REF! | J47: ='Product info'!#REF! -> #REF! | K47: =F47*G47*H47/(100*100*100) -> #REF! | L47: =F47*0.393701 -> #REF! | M47: =G47*0.393701 -> #REF! | N47: =H47*0.393701 -> #REF! | O47: =I47*2.20462 -> #REF! | P47: =Q47&"*"&R47&"*"&S47 -> #REF! | Q47: ='Product info'!#REF! -> #REF! | R47: ='Product info'!#REF! -> #REF! | S47: ='Product info'!#REF! -> #REF! | T47: ='Product info'!#REF! -> #REF! | U47: =Q47*R47*S47/(100*100*100) -> #REF! | V47: =Q47*0.393701 -> #REF! | W47: =R47*0.393701 -> #REF! | X47: =S47*0.393701 -> #REF! | Y47: =T47*2.20462 -> #REF! | Z47: =K47/J47 -> #REF!
A48: ='Product info'!#REF! -> #REF! | B48: ='Product info'!#REF! -> #REF! | C48: ='Product info'!#REF! -> #REF! | D48: ='Product info'!#REF! -> #REF! | E48: =F48&"*"&G48&"*"&H48 -> #REF! | F48: ='Product info'!#REF! -> #REF! | G48: ='Product info'!#REF! -> #REF! | H48: ='Product info'!#REF! -> #REF! | I48: ='Product info'!#REF! -> #REF! | J48: ='Product info'!#REF! -> #REF! | K48: =F48*G48*H48/(100*100*100) -> #REF! | L48: =F48*0.393701 -> #REF! | M48: =G48*0.393701 -> #REF! | N48: =H48*0.393701 -> #REF! | O48: =I48*2.20462 -> #REF! | P48: =Q48&"*"&R48&"*"&S48 -> #REF! | Q48: ='Product info'!#REF! -> #REF! | R48: ='Product info'!#REF! -> #REF! | S48: ='Product info'!#REF! -> #REF! | T48: ='Product info'!#REF! -> #REF! | U48: =Q48*R48*S48/(100*100*100) -> #REF! | V48: =Q48*0.393701 -> #REF! | W48: =R48*0.393701 -> #REF! | X48: =S48*0.393701 -> #REF! | Y48: =T48*2.20462 -> #REF! | Z48: =K48/J48 -> #REF!
A49: ='Product info'!#REF! -> #REF! | B49: ='Product info'!#REF! -> #REF! | C49: ='Product info'!#REF! -> #REF! | D49: ='Product info'!#REF! -> #REF! | E49: =F49&"*"&G49&"*"&H49 -> #REF! | F49: ='Product info'!#REF! -> #REF! | G49: ='Product info'!#REF! -> #REF! | H49: ='Product info'!#REF! -> #REF! | I49: ='Product info'!#REF! -> #REF! | J49: ='Product info'!#REF! -> #REF! | K49: =F49*G49*H49/(100*100*100) -> #REF! | L49: =F49*0.393701 -> #REF! | M49: =G49*0.393701 -> #REF! | N49: =H49*0.393701 -> #REF! | O49: =I49*2.20462 -> #REF! | P49: =Q49&"*"&R49&"*"&S49 -> #REF! | Q49: ='Product info'!#REF! -> #REF! | R49: ='Product info'!#REF! -> #REF! | S49: ='Product info'!#REF! -> #REF! | T49: ='Product info'!#REF! -> #REF! | U49: =Q49*R49*S49/(100*100*100) -> #REF! | V49: =Q49*0.393701 -> #REF! | W49: =R49*0.393701 -> #REF! | X49: =S49*0.393701 -> #REF! | Y49: =T49*2.20462 -> #REF! | Z49: =K49/J49 -> #REF!
A50: ='Product info'!#REF! -> #REF! | B50: ='Product info'!#REF! -> #REF! | C50: ='Product info'!#REF! -> #REF! | D50: ='Product info'!#REF! -> #REF! | E50: =F50&"*"&G50&"*"&H50 -> #REF! | F50: ='Product info'!#REF! -> #REF! | G50: ='Product info'!#REF! -> #REF! | H50: ='Product info'!#REF! -> #REF! | I50: ='Product info'!#REF! -> #REF! | J50: ='Product info'!#REF! -> #REF! | K50: =F50*G50*H50/(100*100*100) -> #REF! | L50: =F50*0.393701 -> #REF! | M50: =G50*0.393701 -> #REF! | N50: =H50*0.393701 -> #REF! | O50: =I50*2.20462 -> #REF! | P50: =Q50&"*"&R50&"*"&S50 -> #REF! | Q50: ='Product info'!#REF! -> #REF! | R50: ='Product info'!#REF! -> #REF! | S50: ='Product info'!#REF! -> #REF! | T50: ='Product info'!#REF! -> #REF! | U50: =Q50*R50*S50/(100*100*100) -> #REF! | V50: =Q50*0.393701 -> #REF! | W50: =R50*0.393701 -> #REF! | X50: =S50*0.393701 -> #REF! | Y50: =T50*2.20462 -> #REF! | Z50: =K50/J50 -> #REF!
A51: ='Product info'!#REF! -> #REF! | B51: ='Product info'!#REF! -> #REF! | C51: ='Product info'!#REF! -> #REF! | D51: ='Product info'!#REF! -> #REF! | E51: =F51&"*"&G51&"*"&H51 -> #REF! | F51: ='Product info'!#REF! -> #REF! | G51: ='Product info'!#REF! -> #REF! | H51: ='Product info'!#REF! -> #REF! | I51: ='Product info'!#REF! -> #REF! | J51: ='Product info'!#REF! -> #REF! | K51: =F51*G51*H51/(100*100*100) -> #REF! | L51: =F51*0.393701 -> #REF! | M51: =G51*0.393701 -> #REF! | N51: =H51*0.393701 -> #REF! | O51: =I51*2.20462 -> #REF! | P51: =Q51&"*"&R51&"*"&S51 -> #REF! | Q51: ='Product info'!#REF! -> #REF! | R51: ='Product info'!#REF! -> #REF! | S51: ='Product info'!#REF! -> #REF! | T51: ='Product info'!#REF! -> #REF! | U51: =Q51*R51*S51/(100*100*100) -> #REF! | V51: =Q51*0.393701 -> #REF! | W51: =R51*0.393701 -> #REF! | X51: =S51*0.393701 -> #REF! | Y51: =T51*2.20462 -> #REF! | Z51: =K51/J51 -> #REF!
A52: ='Product info'!#REF! -> #REF! | B52: ='Product info'!#REF! -> #REF! | C52: ='Product info'!#REF! -> #REF! | D52: ='Product info'!#REF! -> #REF! | E52: =F52&"*"&G52&"*"&H52 -> #REF! | F52: ='Product info'!#REF! -> #REF! | G52: ='Product info'!#REF! -> #REF! | H52: ='Product info'!#REF! -> #REF! | I52: ='Product info'!#REF! -> #REF! | J52: ='Product info'!#REF! -> #REF! | K52: =F52*G52*H52/(100*100*100) -> #REF! | L52: =F52*0.393701 -> #REF! | M52: =G52*0.393701 -> #REF! | N52: =H52*0.393701 -> #REF! | O52: =I52*2.20462 -> #REF! | P52: =Q52&"*"&R52&"*"&S52 -> #REF! | Q52: ='Product info'!#REF! -> #REF! | R52: ='Product info'!#REF! -> #REF! | S52: ='Product info'!#REF! -> #REF! | T52: ='Product info'!#REF! -> #REF! | U52: =Q52*R52*S52/(100*100*100) -> #REF! | V52: =Q52*0.393701 -> #REF! | W52: =R52*0.393701 -> #REF! | X52: =S52*0.393701 -> #REF! | Y52: =T52*2.20462 -> #REF! | Z52: =K52/J52 -> #REF!
A53: ='Product info'!#REF! -> #REF! | B53: ='Product info'!#REF! -> #REF! | C53: ='Product info'!#REF! -> #REF! | D53: ='Product info'!#REF! -> #REF! | E53: =F53&"*"&G53&"*"&H53 -> #REF! | F53: ='Product info'!#REF! -> #REF! | G53: ='Product info'!#REF! -> #REF! | H53: ='Product info'!#REF! -> #REF! | I53: ='Product info'!#REF! -> #REF! | J53: ='Product info'!#REF! -> #REF! | K53: =F53*G53*H53/(100*100*100) -> #REF! | L53: =F53*0.393701 -> #REF! | M53: =G53*0.393701 -> #REF! | N53: =H53*0.393701 -> #REF! | O53: =I53*2.20462 -> #REF! | P53: =Q53&"*"&R53&"*"&S53 -> #REF! | Q53: ='Product info'!#REF! -> #REF! | R53: ='Product info'!#REF! -> #REF! | S53: ='Product info'!#REF! -> #REF! | T53: ='Product info'!#REF! -> #REF! | U53: =Q53*R53*S53/(100*100*100) -> #REF! | V53: =Q53*0.393701 -> #REF! | W53: =R53*0.393701 -> #REF! | X53: =S53*0.393701 -> #REF! | Y53: =T53*2.20462 -> #REF! | Z53: =K53/J53 -> #REF!
A54: ='Product info'!#REF! -> #REF! | B54: ='Product info'!#REF! -> #REF! | C54: ='Product info'!#REF! -> #REF! | D54: ='Product info'!#REF! -> #REF! | E54: =F54&"*"&G54&"*"&H54 -> #REF! | F54: ='Product info'!#REF! -> #REF! | G54: ='Product info'!#REF! -> #REF! | H54: ='Product info'!#REF! -> #REF! | I54: ='Product info'!#REF! -> #REF! | J54: ='Product info'!#REF! -> #REF! | K54: =F54*G54*H54/(100*100*100) -> #REF! | L54: =F54*0.393701 -> #REF! | M54: =G54*0.393701 -> #REF! | N54: =H54*0.393701 -> #REF! | O54: =I54*2.20462 -> #REF! | P54: =Q54&"*"&R54&"*"&S54 -> #REF! | Q54: ='Product info'!#REF! -> #REF! | R54: ='Product info'!#REF! -> #REF! | S54: ='Product info'!#REF! -> #REF! | T54: ='Product info'!#REF! -> #REF! | U54: =Q54*R54*S54/(100*100*100) -> #REF! | V54: =Q54*0.393701 -> #REF! | W54: =R54*0.393701 -> #REF! | X54: =S54*0.393701 -> #REF! | Y54: =T54*2.20462 -> #REF! | Z54: =K54/J54 -> #REF!
A55: ='Product info'!#REF! -> #REF! | B55: ='Product info'!#REF! -> #REF! | C55: ='Product info'!#REF! -> #REF! | D55: ='Product info'!#REF! -> #REF! | E55: =F55&"*"&G55&"*"&H55 -> #REF! | F55: ='Product info'!#REF! -> #REF! | G55: ='Product info'!#REF! -> #REF! | H55: ='Product info'!#REF! -> #REF! | I55: ='Product info'!#REF! -> #REF! | J55: ='Product info'!#REF! -> #REF! | K55: =F55*G55*H55/(100*100*100) -> #REF! | L55: =F55*0.393701 -> #REF! | M55: =G55*0.393701 -> #REF! | N55: =H55*0.393701 -> #REF! | O55: =I55*2.20462 -> #REF! | P55: =Q55&"*"&R55&"*"&S55 -> #REF! | Q55: ='Product info'!#REF! -> #REF! | R55: ='Product info'!#REF! -> #REF! | S55: ='Product info'!#REF! -> #REF! | T55: ='Product info'!#REF! -> #REF! | U55: =Q55*R55*S55/(100*100*100) -> #REF! | V55: =Q55*0.393701 -> #REF! | W55: =R55*0.393701 -> #REF! | X55: =S55*0.393701 -> #REF! | Y55: =T55*2.20462 -> #REF! | Z55: =K55/J55 -> #REF!
... A339: ='Product info'!#REF! -> #REF! | B339: ='Product info'!#REF! -> #REF! | C339: ='Product info'!#REF! -> #REF! | D339: ='Product info'!#REF! -> #REF! | E339: =F339&"*"&G339&"*"&H339 -> #REF! | F339: ='Product info'!#REF! -> #REF! | G339: ='Product info'!#REF! -> #REF! | H339: ='Product info'!#REF! -> #REF! | I339: ='Product info'!#REF! -> #REF! | J339: ='Product info'!#REF! -> #REF! | K339: =F339*G339*H339/(100*100*100) -> #REF! | L339: =F339*0.393701 -> #REF! | M339: =G339*0.393701 -> #REF! | N339: =H339*0.393701 -> #REF! | O339: =I339*2.20462 -> #REF! | P339: =Q339&"*"&R339&"*"&S339 -> #REF! | Q339: ='Product info'!#REF! -> #REF! | R339: ='Product info'!#REF! -> #REF! | S339: ='Product info'!#REF! -> #REF! | T339: ='Product info'!#REF! -> #REF! | U339: =Q339*R339*S339/(100*100*100) -> #REF! | V339: =Q339*0.393701 -> #REF! | W339: =R339*0.393701 -> #REF! | X339: =S339*0.393701 -> #REF! | Y339: =T339*2.20462 -> #REF! | Z339: =K339/J339 -> #REF!
A340: ='Product info'!A6 -> B08BG74Q65 | B340: ='Product info'!F6 -> 0 | C340: ='Product info'!G6 -> 7E-GZIK-FILJ | D340: ='Product info'!H6 -> 0 | E340: =F340&"*"&G340&"*"&H340 -> 51.5*39.7*46.5 | F340: ='Product info'!O6 -> 51.5 | G340: ='Product info'!P6 -> 39.7 | H340: ='Product info'!Q6 -> 46.5 | I340: ='Product info'!N6 -> 5.5 | J340: ='Product info'!M6 -> 6 | K340: =F340*G340*H340/(100*100*100) -> 0.095071575 | L340: =F340*0.393701 -> 20.275602 | M340: =G340*0.393701 -> 15.62993 | N340: =H340*0.393701 -> 18.307097 | O340: =I340*2.20462 -> 12.12541 | P340: =Q340&"*"&R340&"*"&S340 -> 28*24*18 | Q340: ='Product info'!S6 -> 28 | R340: ='Product info'!T6 -> 24 | S340: ='Product info'!U6 -> 18 | T340: ='Product info'!R6 -> 0.84 | U340: =Q340*R340*S340/(100*100*100) -> 0.012096 | V340: =Q340*0.393701 -> 11.023628 | W340: =R340*0.393701 -> 9.448824 | X340: =S340*0.393701 -> 7.086618 | Y340: =T340*2.20462 -> 1.8518808 | Z340: =K340/J340 -> 0.015845263
A341: ='Product info'!A7 -> 8719992661190 | B341: ='Product info'!F7 -> 0 | C341: ='Product info'!G7 -> 0 | D341: ='Product info'!H7 -> 0 | E341: =F341&"*"&G341&"*"&H341 -> 40*52*59 | F341: ='Product info'!O7 -> 40 | G341: ='Product info'!P7 -> 52 | H341: ='Product info'!Q7 -> 59 | I341: ='Product info'!N7 -> 9.9 | J341: ='Product info'!M7 -> 6 | K341: =F341*G341*H341/(100*100*100) -> 0.12272 | L341: =F341*0.393701 -> 15.74804 | M341: =G341*0.393701 -> 20.472452 | N341: =H341*0.393701 -> 23.228359 | O341: =I341*2.20462 -> 21.825738 | P341: =Q341&"*"&R341&"*"&S341 -> 25*39*19 | Q341: ='Product info'!S7 -> 25 | R341: ='Product info'!T7 -> 39 | S341: ='Product info'!U7 -> 19 | T341: ='Product info'!R7 -> 1.5 | U341: =Q341*R341*S341/(100*100*100) -> 0.018525 | V341: =Q341*0.393701 -> 9.842525 | W341: =R341*0.393701 -> 15.354339 | X341: =S341*0.393701 -> 7.480319 | Y341: =T341*2.20462 -> 3.30693 | Z341: =K341/J341 -> 0.020453333
A342: ='Product info'!A8 -> B08BG695P2 | B342: ='Product info'!F8 -> 0 | C342: ='Product info'!G8 -> FP-S3KC-OPLV | D342: ='Product info'!H8 -> 0 | E342: =F342&"*"&G342&"*"&H342 -> 51.5*39.7*55.5 | F342: ='Product info'!O8 -> 51.5 | G342: ='Product info'!P8 -> 39.7 | H342: ='Product info'!Q8 -> 55.5 | I342: ='Product info'!N8 -> 9.2 | J342: ='Product info'!M8 -> 6 | K342: =F342*G342*H342/(100*100*100) -> 0.11347253 | L342: =F342*0.393701 -> 20.275602 | M342: =G342*0.393701 -> 15.62993 | N342: =H342*0.393701 -> 21.850406 | O342: =I342*2.20462 -> 20.282504 | P342: =Q342&"*"&R342&"*"&S342 -> 38*24*18 | Q342: ='Product info'!S8 -> 38 | R342: ='Product info'!T8 -> 24 | S342: ='Product info'!U8 -> 18 | T342: ='Product info'!R8 -> 1.43 | U342: =Q342*R342*S342/(100*100*100) -> 0.016416 | V342: =Q342*0.393701 -> 14.960638 | W342: =R342*0.393701 -> 9.448824 | X342: =S342*0.393701 -> 7.086618 | Y342: =T342*2.20462 -> 3.1526066 | Z342: =K342/J342 -> 0.018912088
A343: ='Product info'!A9 -> B07Q3FVXS9 | B343: ='Product info'!F9 -> 0 | C343: ='Product info'!G9 -> EW-IO2U-1J4Q | D343: ='Product info'!H9 -> 0 | E343: =F343&"*"&G343&"*"&H343 -> 45*50*55 | F343: ='Product info'!O9 -> 45 | G343: ='Product info'!P9 -> 50 | H343: ='Product info'!Q9 -> 55 | I343: ='Product info'!N9 -> 19 | J343: ='Product info'!M9 -> 60 | K343: =F343*G343*H343/(100*100*100) -> 0.12375 | L343: =F343*0.393701 -> 17.716545 | M343: =G343*0.393701 -> 19.68505 | N343: =H343*0.393701 -> 21.653555 | O343: =I343*2.20462 -> 41.88778 | P343: =Q343&"*"&R343&"*"&S343 -> 25*26*6 | Q343: ='Product info'!S9 -> 25 | R343: ='Product info'!T9 -> 26 | S343: ='Product info'!U9 -> 6 | T343: ='Product info'!R9 -> 0.28 | U343: =Q343*R343*S343/(100*100*100) -> 0.0039 | V343: =Q343*0.393701 -> 9.842525 | W343: =R343*0.393701 -> 10.236226 | X343: =S343*0.393701 -> 2.362206 | Y343: =T343*2.20462 -> 0.6172936 | Z343: =K343/J343 -> 0.0020625
A344: ='Product info'!A10 -> 8720618229946 | B344: ='Product info'!F10 -> 0 | C344: ='Product info'!G10 -> 0 | D344: ='Product info'!H10 -> 0 | E344: =F344&"*"&G344&"*"&H344 -> 26*44*39.5 | F344: ='Product info'!O10 -> 26 | G344: ='Product info'!P10 -> 44 | H344: ='Product info'!Q10 -> 39.5 | I344: ='Product info'!N10 -> 11.3 | J344: ='Product info'!M10 -> 13 | K344: =F344*G344*H344/(100*100*100) -> 0.045188 | L344: =F344*0.393701 -> 10.236226 | M344: =G344*0.393701 -> 17.322844 | N344: =H344*0.393701 -> 15.55119 | O344: =I344*2.20462 -> 24.912206 | P344: =Q344&"*"&R344&"*"&S344 -> 24*36.5*2.7 | Q344: ='Product info'!S10 -> 24 | R344: ='Product info'!T10 -> 36.5 | S344: ='Product info'!U10 -> 2.7 | T344: ='Product info'!R10 -> 0.8 | U344: =Q344*R344*S344/(100*100*100) -> 0.0023652 | V344: =Q344*0.393701 -> 9.448824 | W344: =R344*0.393701 -> 14.370087 | X344: =S344*0.393701 -> 1.0629927 | Y344: =T344*2.20462 -> 1.763696 | Z344: =K344/J344 -> 0.003476
A345: ='Product info'!A11 -> 8720618229953 | B345: ='Product info'!F11 -> 0 | C345: ='Product info'!G11 -> 0 | D345: ='Product info'!H11 -> 0 | E345: =F345&"*"&G345&"*"&H345 -> 26*44*39.5 | F345: ='Product info'!O11 -> 26 | G345: ='Product info'!P11 -> 44 | H345: ='Product info'!Q11 -> 39.5 | I345: ='Product info'!N11 -> 11.3 | J345: ='Product info'!M11 -> 13 | K345: =F345*G345*H345/(100*100*100) -> 0.045188 | L345: =F345*0.393701 -> 10.236226 | M345: =G345*0.393701 -> 17.322844 | N345: =H345*0.393701 -> 15.55119 | O345: =I345*2.20462 -> 24.912206 | P345: =Q345&"*"&R345&"*"&S345 -> 24*36.5*2.7 | Q345: ='Product info'!S11 -> 24 | R345: ='Product info'!T11 -> 36.5 | S345: ='Product info'!U11 -> 2.7 | T345: ='Product info'!R11 -> 0.8 | U345: =Q345*R345*S345/(100*100*100) -> 0.0023652 | V345: =Q345*0.393701 -> 9.448824 | W345: =R345*0.393701 -> 14.370087 | X345: =S345*0.393701 -> 1.0629927 | Y345: =T345*2.20462 -> 1.763696 | Z345: =K345/J345 -> 0.003476
A346: ='Product info'!#REF! -> #REF! | B346: ='Product info'!#REF! -> #REF! | C346: ='Product info'!#REF! -> #REF! | D346: ='Product info'!#REF! -> #REF! | E346: =F346&"*"&G346&"*"&H346 -> #REF! | F346: ='Product info'!#REF! -> #REF! | G346: ='Product info'!#REF! -> #REF! | H346: ='Product info'!#REF! -> #REF! | I346: ='Product info'!#REF! -> #REF! | J346: ='Product info'!#REF! -> #REF! | K346: =F346*G346*H346/(100*100*100) -> #REF! | L346: =F346*0.393701 -> #REF! | M346: =G346*0.393701 -> #REF! | N346: =H346*0.393701 -> #REF! | O346: =I346*2.20462 -> #REF! | P346: =Q346&"*"&R346&"*"&S346 -> #REF! | Q346: ='Product info'!#REF! -> #REF! | R346: ='Product info'!#REF! -> #REF! | S346: ='Product info'!#REF! -> #REF! | T346: ='Product info'!#REF! -> #REF! | U346: =Q346*R346*S346/(100*100*100) -> #REF! | V346: =Q346*0.393701 -> #REF! | W346: =R346*0.393701 -> #REF! | X346: =S346*0.393701 -> #REF! | Y346: =T346*2.20462 -> #REF! | Z346: =K346/J346 -> #REF!
A347: ='Product info'!#REF! -> #REF! | B347: ='Product info'!#REF! -> #REF! | C347: ='Product info'!#REF! -> #REF! | D347: ='Product info'!#REF! -> #REF! | E347: =F347&"*"&G347&"*"&H347 -> #REF! | F347: ='Product info'!#REF! -> #REF! | G347: ='Product info'!#REF! -> #REF! | H347: ='Product info'!#REF! -> #REF! | I347: ='Product info'!#REF! -> #REF! | J347: ='Product info'!#REF! -> #REF! | K347: =F347*G347*H347/(100*100*100) -> #REF! | L347: =F347*0.393701 -> #REF! | M347: =G347*0.393701 -> #REF! | N347: =H347*0.393701 -> #REF! | O347: =I347*2.20462 -> #REF! | P347: =Q347&"*"&R347&"*"&S347 -> #REF! | Q347: ='Product info'!#REF! -> #REF! | R347: ='Product info'!#REF! -> #REF! | S347: ='Product info'!#REF! -> #REF! | T347: ='Product info'!#REF! -> #REF! | U347: =Q347*R347*S347/(100*100*100) -> #REF! | V347: =Q347*0.393701 -> #REF! | W347: =R347*0.393701 -> #REF! | X347: =S347*0.393701 -> #REF! | Y347: =T347*2.20462 -> #REF! | Z347: =K347/J347 -> #REF!
...

Sheet Inspection points
A1: ID (ASIN/ EAN) | B1: Product name | C1: Inspection point 1 | D1: Inspection point 2 | E1: Inspection point 3 | F1: Inspection point 4 | G1: Inspection point 5 | H1: Inspection point 6 | I1: Inspection point 7 | J1: Inspection point 8 | K1: Inspection point 9 | L1: Inspection point 10 | M1: Inspection point 11 | N1: Inspection point 12 | O1: Inspection point 13 | P1: Inspection point 14 | Q1: Inspection point 15 | R1: Inspection point 16 | S1: Inspection point 17 | T1: Inspection point 18 | U1: Inspection point 19 | V1: Inspection point 20 | W1: Inspection point 21 | X1: Inspection point 22 | Y1: Inspection point 23 | Z1: Inspection point 24 | AA1: Inspection point 25 | AB1: Inspection point 26 | AC1: Inspection point 27 | AD1: Inspection point 28 | AE1: Inspection point 29 | AF1: Inspection point 30 | AG1: Inspection point 31 | AH1: Inspection point 32 | AI1: Inspection point 33 | AJ1: Inspection point 34 | AK1: Inspection point 35 | AL1: Inspection point 36 | AM1: Inspection point 37 | AN1: Inspection point 38 | AO1: Inspection point 39 | AP1: Inspection point 40 | AQ1: Inspection point 41 | AR1: Inspection point 42 | AS1: Inspection point 43 | AT1: Inspection point 44 | AU1: Inspection point 45 | AV1: Inspection point 46 | AW1: Inspection point 47 | AX1: Inspection point 48 | AY1: Inspection point 49 | AZ1: Inspection point 50 | BA1: Inspection point 51 | BB1: Inspection point 52 | BC1: Inspection point 53 | BD1: Inspection point 54 | BE1: Inspection point 55 | BF1: Inspection point 56 | BG1: Inspection point 57 | BH1: Inspection point 58 | BI1: Inspection point 59 | BJ1: Inspection point 60
A2: B07NS8B464 | B2: =_xlfn.XLOOKUP(A2,'Product info'!A:A,'Product info'!C:C,,2) -> Blanket koala
A3: B07Q3FVXS9 | B3: =_xlfn.XLOOKUP(A3,'Product info'!A:A,'Product info'!C:C,,2) -> Rabbit blanket | C3: If a product is packaged in a box, check if there is any loose space inside the box. There needs to be some kind of foam or plastic inside to protect the product during shipping | D3: If a product is packaged in a box, hold it in front of you and shake it 10 times. If you hear the product or any of its parts moving, there is too much loose space in the box and this is not accepted | E3: If a product is packaged in a poly bag, check if it is packaged as tight as possible. There should be no loose plastic on the outside of the product | F3: If a product or any of its components is packaged in a polybag, it must be perforated with 4 holes, each 6.4mm thick. | G3: If a product or any of its components is packaged in a polybag, the thickness of the poly bag should be at least 1.5mil (thousandt of an inch). The bag must also be completely sealed and transparent | H3: If a product or any of its components is packaged in a polybag, check if it contains the correct suffocation warning label, printed transparently on the front and the back, in the center, in 33 by 21 centimeters. | I3: Check if any polyfoam is used to protect the product inside the packaging. Could this foam come loose easily and ruin the product (many small foam parts being everywhere on the product)? | J3: If the product stays packaged like this for more than 2 months, do you expect it will have folds or creases on the products? Do you already see this forming a little bit now? | K3: The UPC label that is printed on the packaging should NOT be printed on a reflective surface, as this prevents scanners from reading the barcode directly. Please ensure that the product labels are not reflective when applying them to units. | L3: Checkif the production matches with the SKU barcode, carton dimensions and carton weight with the product information sheet | M3: Outer cartons weighing more than 15kg must be marked "CAUTION Heavy Package - Team Lift" on all sides and on the top | N3: Check if the outer carton contains all the mandatory icons (handle with care, this side up, keep dry) on all sides. The direction of 'This side Up' should be towards the top of the outer carton. | O3: Check if the outer carton contains the text ('Think before you lift') two times on the openings of the outer carton | P3: Check if the outer carton contains a batch number that matches the batch number that is on the inner product packaging | Q3: Check if when you open the outer carton, that there is no bad smell | R3: If it is a textile product, check if the text "Warning, Keep Away from Fire" is stitched on the product | S3: Check if the importer US adress on the packaging is '2501 Chatham Rd # N, Springfield, IL 62704-4188, United States' | T3: Check if the importer EU address on the packaging is 'Rietgansstraat 5, 3882 JD Putten, The Netherlands' | U3: Check if the importer UK address on the packaging is 'Lytchett House, 13 Freeland Park, Wareham Road, Poole, Dorset, BH16 6FA, UK' | V3: Check if the importer, manufacturer, UK Responsible Person and EU Responsible person are on the outer packaging with 'SH International B.V.' As the company name, 'Rietgansstraat 5, 3882 JD Putten, The Netherlands' as the address, 'support@shinternationalbv.com' as the e-mail and 'shinternationalbv.com'as the website | W3: Check if 'Designed in the Netherlands, Produced in China' is on the package | X3: Check if the EAN and Weight is on the outer packaging. EAN should match with the product information sheet, Content should be similar to the 'Included in set' in the product information sheet and the Weight should be within 100 grams of the packaging weight | Y3: Check if the product packaging contains a sticker with the batch number and manufacturing date | Z3: Check if when you open the product packaging that there is no bad smell | AA3: If the product has a certification label, check if it is attached to the outer packaging and if it contains EAN, ASIN, Age, Model number and Material | AB3: Check if any polyfoam is used to protect the product inside the packaging. Could this foam come loose easily and ruin the product (many small foam parts being everywhere on the product)? | AC3: Check if the manuals, thank you notes, boxes, certification labels and normal labels from production match with the ones from the product information sheet | AD3: If the product is vacuum compressed, check if the vacuum seal is intact with no leaks or tears | AE3: If the product is vacuum compressed, check if it is tight enough. It should be snug around the product with minimal air pockets | AF3: If the product is vacuum compressed, verify if it is thick enough so that it is durable and puncture-resistant
A4: B08BP7ZNWG | B4: =_xlfn.XLOOKUP(A4,'Product info'!A:A,'Product info'!C:C,,2) -> #N/A
A5: B08BPHXFYV | B5: =_xlfn.XLOOKUP(A5,'Product info'!A:A,'Product info'!C:C,,2) -> #N/A
A6: B08CHNBL9Y | B6: =_xlfn.XLOOKUP(A6,'Product info'!A:A,'Product info'!C:C,,2) -> #N/A | C6: =IF(D6="AMZ",F6,G6) -> 0
A7: B08CKS36CP | B7: =_xlfn.XLOOKUP(A7,'Product info'!A:A,'Product info'!C:C,,2) -> #N/A | C7: If a product is packaged in a box, check if there is any loose space inside the box. There needs to be some kind of foam or plastic inside to protect the product during shipping | D7: If a product is packaged in a box, hold it in front of you and shake it 10 times. If you hear the product or any of its parts moving, there is too much loose space in the box and this is not accepted | E7: If a product is packaged in a poly bag, check if it is packaged as tight as possible. There should be no loose plastic on the outside of the product | F7: If a product or any of its components is packaged in a polybag, it must be perforated with 4 holes, each 6.4mm thick. | G7: If a product or any of its components is packaged in a polybag, the thickness of the poly bag should be at least 1.5mil (thousandt of an inch). The bag must also be completely sealed and transparent | H7: If a product or any of its components is packaged in a polybag, check if it contains the correct suffocation warning label, printed transparently on the front and the back, in the center, in 33 by 21 centimeters. | I7: Check if any polyfoam is used to protect the product inside the packaging. Could this foam come loose easily and ruin the product (many small foam parts being everywhere on the product)? | J7: If the product stays packaged like this for more than 2 months, do you expect it will have folds or creases on the products? Do you already see this forming a little bit now? | K7: The UPC label that is printed on the packaging should NOT be printed on a reflective surface, as this prevents scanners from reading the barcode directly. Please ensure that the product labels are not reflective when applying them to units. | L7: Checkif the production matches with the SKU barcode, carton dimensions and carton weight with the product information sheet | M7: Outer cartons weighing more than 15kg must be marked "CAUTION Heavy Package - Team Lift" on all sides and on the top | N7: Check if the outer carton contains all the mandatory icons (handle with care, this side up, keep dry) on all sides. The direction of 'This side Up' should be towards the top of the outer carton. | O7: Check if the outer carton contains the text ('Think before you lift') two times on the openings of the outer carton | P7: Check if the outer carton contains a batch number that matches the batch number that is on the inner product packaging | Q7: Check if when you open the outer carton, that there is no bad smell | R7: If it is a textile product, check if the text "Warning, Keep Away from Fire" is stitched on the product | S7: Check if the importer US adress on the packaging is '2501 Chatham Rd # N, Springfield, IL 62704-4188, United States' | T7: Check if the importer EU address on the packaging is 'Rietgansstraat 5, 3882 JD Putten, The Netherlands' | U7: Check if the importer UK address on the packaging is 'Lytchett House, 13 Freeland Park, Wareham Road, Poole, Dorset, BH16 6FA, UK' | V7: Check if the importer, manufacturer, UK Responsible Person and EU Responsible person are on the outer packaging with 'SH International B.V.' As the company name, 'Rietgansstraat 5, 3882 JD Putten, The Netherlands' as the address, 'support@shinternationalbv.com' as the e-mail and 'shinternationalbv.com'as the website | W7: Check if 'Designed in the Netherlands, Produced in China' is on the package | X7: Check if the EAN and Weight is on the outer packaging. EAN should match with the product information sheet, Content should be similar to the 'Included in set' in the product information sheet and the Weight should be within 100 grams of the packaging weight | Y7: Check if the product packaging contains a sticker with the batch number and manufacturing date | Z7: Check if when you open the product packaging that there is no bad smell | AA7: If the product has a certification label, check if it is attached to the outer packaging and if it contains EAN, ASIN, Age, Model number and Material | AB7: Check if any polyfoam is used to protect the product inside the packaging. Could this foam come loose easily and ruin the product (many small foam parts being everywhere on the product)? | AC7: Check if the manuals, thank you notes, boxes, certification labels and normal labels from production match with the ones from the product information sheet | AD7: If the product is vacuum compressed, check if the vacuum seal is intact with no leaks or tears | AE7: If the product is vacuum compressed, check if it is tight enough. It should be snug around the product with minimal air pockets | AF7: If the product is vacuum compressed, verify if it is thick enough so that it is durable and puncture-resistant
A8: B08CKVQD66 | B8: =_xlfn.XLOOKUP(A8,'Product info'!A:A,'Product info'!C:C,,2) -> #N/A
A9: B08CKW16F7 | B9: =_xlfn.XLOOKUP(A9,'Product info'!A:A,'Product info'!C:C,,2) -> Blanket fox
A10: B08FCLNXWM | B10: =_xlfn.XLOOKUP(A10,'Product info'!A:A,'Product info'!C:C,,2) -> #N/A
A11: B08RJ1BNVF | B11: =_xlfn.XLOOKUP(A11,'Product info'!A:A,'Product info'!C:C,,2) -> #N/A
A12: B09D8CDDK2 | B12: =_xlfn.XLOOKUP(A12,'Product info'!A:A,'Product info'!C:C,,2) -> #N/A
A13: B09D8CG4P9 | B13: =_xlfn.XLOOKUP(A13,'Product info'!A:A,'Product info'!C:C,,2) -> #N/A | C13: If a product is packaged in a box, check if there is any loose space inside the box. There needs to be some kind of foam or plastic inside to protect the product during shipping | D13: If a product is packaged in a box, hold it in front of you and shake it 10 times. If you hear the product or any of its parts moving, there is too much loose space in the box and this is not accepted | E13: If a product is packaged in a poly bag, check if it is packaged as tight as possible. There should be no loose plastic on the outside of the product | F13: If a product or any of its components is packaged in a polybag, it must be perforated with 4 holes, each 6.4mm thick. | G13: If a product or any of its components is packaged in a polybag, the thickness of the poly bag should be at least 1.5mil (thousandt of an inch). The bag must also be completely sealed and transparent | H13: If a product or any of its components is packaged in a polybag, check if it contains the correct suffocation warning label, printed transparently on the front and the back, in the center, in 33 by 21 centimeters. | I13: Check if any polyfoam is used to protect the product inside the packaging. Could this foam come loose easily and ruin the product (many small foam parts being everywhere on the product)? | J13: If the product stays packaged like this for more than 2 months, do you expect it will have folds or creases on the products? Do you already see this forming a little bit now? | K13: The UPC label that is printed on the packaging should NOT be printed on a reflective surface, as this prevents scanners from reading the barcode directly. Please ensure that the product labels are not reflective when applying them to units. | L13: Checkif the production matches with the SKU barcode, carton dimensions and carton weight with the product information sheet | M13: Outer cartons weighing more than 15kg must be marked "CAUTION Heavy Package - Team Lift" on all sides and on the top | N13: Check if the outer carton contains all the mandatory icons (handle with care, this side up, keep dry) on all sides. The direction of 'This side Up' should be towards the top of the outer carton. | O13: Check if the outer carton contains the text ('Think before you lift') two times on the openings of the outer carton | P13: Check if the outer carton contains a batch number that matches the batch number that is on the inner product packaging | Q13: Check if when you open the outer carton, that there is no bad smell | R13: If it is a textile product, check if the text "Warning, Keep Away from Fire" is stitched on the product | S13: Check if the importer US adress on the packaging is '2501 Chatham Rd # N, Springfield, IL 62704-4188, United States' | T13: Check if the importer EU address on the packaging is 'Rietgansstraat 5, 3882 JD Putten, The Netherlands' | U13: Check if the importer UK address on the packaging is 'Lytchett House, 13 Freeland Park, Wareham Road, Poole, Dorset, BH16 6FA, UK' | V13: Check if the importer, manufacturer, UK Responsible Person and EU Responsible person are on the outer packaging with 'SH International B.V.' As the company name, 'Rietgansstraat 5, 3882 JD Putten, The Netherlands' as the address, 'support@shinternationalbv.com' as the e-mail and 'shinternationalbv.com'as the website | W13: Check if 'Designed in the Netherlands, Produced in China' is on the package | X13: Check if the EAN and Weight is on the outer packaging. EAN should match with the product information sheet, Content should be similar to the 'Included in set' in the product information sheet and the Weight should be within 100 grams of the packaging weight | Y13: Check if the product packaging contains a sticker with the batch number and manufacturing date | Z13: Check if when you open the product packaging that there is no bad smell | AA13: If the product has a certification label, check if it is attached to the outer packaging and if it contains EAN, ASIN, Age, Model number and Material | AB13: Check if any polyfoam is used to protect the product inside the packaging. Could this foam come loose easily and ruin the product (many small foam parts being everywhere on the product)? | AC13: Check if the manuals, thank you notes, boxes, certification labels and normal labels from production match with the ones from the product information sheet | AD13: If the product is vacuum compressed, check if the vacuum seal is intact with no leaks or tears | AE13: If the product is vacuum compressed, check if it is tight enough. It should be snug around the product with minimal air pockets | AF13: If the product is vacuum compressed, verify if it is thick enough so that it is durable and puncture-resistant
A14: B09D8DS6FV | B14: =_xlfn.XLOOKUP(A14,'Product info'!A:A,'Product info'!C:C,,2) -> #N/A
A15: B09JK66341 | B15: =_xlfn.XLOOKUP(A15,'Product info'!A:A,'Product info'!C:C,,2) -> #N/A
A16: B09LDCG6YK | B16: =_xlfn.XLOOKUP(A16,'Product info'!A:A,'Product info'!C:C,,2) -> #N/A
